Workbook

Sheet COA_Cat
B2: Categ_Key | C2: Acc_Categ_Name | D2: Acc_Cate_Nam_Arb | E2: Corrs_Statment
B3: 1 | C3: Long Term Fixed Assets | D3: الأصول طويلة الأجل | E3: Balance Sheet
B4: 2 | C4: Cash & Cash Eqivlant | D4: أصول متداولة النقدية بالبنوك والصندوق | E4: Balance Sheet
B5: 3 | C5: Current Assets | D5: أصول متداولة | E5: Balance Sheet
B6: 4 | C6: Current Liabilities | D6: الخصوم قصيرة الأجل | E6: Balance Sheet
B7: 5 | C7: Shareholder Equity | D7: حقوق مساهمين | E7: Balance Sheet
B8: 6 | C8: Direct Operating Revenue | D8: المبيعات | E8: Income Statement
B9: 7 | C9: Direct Operating Cost | D9: تكلفة المبيعات | E9: Income Statement
B10: 8 | C10: Admins & Gen Expen | D10: مصروفات أدارية وعمومية | E10: Income Statement

Sheet Itm_Cat
A1: Item_Cat_ID | B1: SAL_EINV_ITEM | C1: Item_Categ | D1: SAL_Acc_Key | E1: PUR_Acc_Key | F1: PUR_EINV_ITEM
A2: 1 | B2: EG-692383735-10007581 | C2: Usering Services - Haring Users & Uniform | D2: 18 | E2: 27
A3: 2 | B3: EG-692383735-100075960 | C3: food and baverage | D3: 18 | E3: 21
A4: 3 | B4: EG-692383735-10007579 | C4: Entertainments Activities & Training | D4: 18 | E4: 28
A5: 4 | B5: EG-692383735-10007579 | C5: Both Production & Interior Decoration | D5: 18 | E5: 24
A6: 5 | B6: EG-692383735-10007579 | C6: Branding Eliments in door & outdoor advertisment customized printed items | D6: 18 | E6: 25
A7: 6 | B7: EG-692383735-10007579 | C7: Sound & Light Equipments | D7: 18 | E7: 29
A8: 7 | B8: EG-692383735-10007579 | C8: Event Photo & Vido documetnery services | D8: 18 | E8: 26
A9: 8 | B9: EG-692383735-10007581 | C9: Incentive House Management Fees | D9: 18 | E9: 18
A10: 9 | B10: EG-692383735-10007605 | C10: transfers & transportation among the event | D10: 18 | E10: 20
A11: 10 | B11: EG-692383735-10007597 | C11: Meeting Rooms & Meeting Area Accomodation | D11: 18 | E11: 22
A12: 11 | B12: EG-692383735-10007597 | C12: Hotel Accomodation | D12: 18 | E12: 22
A13: 12 | B13: EG-692383735-10007597 | C13: Land Arrangments | D13: 18 | E13: 28
... A21: 20 | B21: N/A | C21: Professional Fees | D21: 18 | E21: 33

Sheet COA_Mtble
B2: Acc_Name | C2: Acc_Name_Arb | D2: Acc_Key | E2: Categ_Key
B3: Establishment Cost | C3: ح / مصاريف التأسيس وما قبل التشغيل | D3: 1 | E3: 1
B4: Fixed Assets - Computre & Lap tops | C4: أصول ثابتة - كمبيوتر | D4: 2 | E4: 1
B5: Fixed Assets - Vehicle | C5: ح / اصول طويلة الأجل -سيارات | D5: 3 | E5: 1
B6: Cash at Bank - ENBD Current Account | C6: النقدية بالنبوك والصندوق- جنية مصري | D6: 4 | E6: 2
B7: Cash at Bank - ENBD Euro Account | C7: النقدية بالنبوك والصندوق- يورو | D7: 5 | E7: 2
B8: Cash at Bank - ENBD Saving Account | C8: النقدية بالنبوك والصندوق- جنية مصري توفير | D8: 6 | E8: 2
B9: Cash at Bank - ENBD USD Account | C9: النقدية بالنبوك والصندوق- دولار أمريكي | D9: 7 | E9: 2
B10: Cash in Transit | C10: النقدية بالطريق | D10: 8 | E10: 2
B11: Cash on Hand | C11: النقدية بالصندوق | D11: 9 | E11: 2
B12: CHQ Contra Account | C12: شيكات برسم الدفع | D12: 43 | E12: 3
B13: Accounts Receivables | C13: مدينون وأرصدة عملاء | D13: 10 | E13: 3
B14: Staff Loans & Petty Cash settlement Account | C14: مدينون سلف وعهد العاملين | D14: 11 | E14: 3
... B45: Admin & Gen Expen _Staff Food & Eternal Meeting | C45: مصروفات أدارية وعمومية - مصروفات واجبات وأجتماعات خارجية | D45: 42 | E45: 8

Sheet EINV_Itm_Mtble
A1: Item_Categ | B1: Item_Cat_ID | C1: Einvoice Key Code Name
A2: F&B | B2: 2 | C2: وجبات كاترينج | E2: Code ID | F2: Item Categorg
A3: CARMIN | B3: 18 | C3: 016320/BLEED LINE | E3: 1 | F3: Air Tickets
A4: CARMIN | B4: 18 | C4: AIR FILTER ELEMENT | E4: 2 | F4: Accomodation
A5: CARMIN | B5: 18 | C5: BRAKEPAD WEAR SENSOR | E5: 3 | F5: Transfers
A6: Trans | B6: 9 | C6: خدمات الانتقال | E6: 4 | F6: Avenue Rental Charges
A7: Enter | B7: 3 | C7: إدارة الأعمال والخدمات الاستشارية | E7: 5 | F7: Stage Sound & Light Fixtures
A8: ACC | B8: 11 | C8: خدمات الإقامة المؤقتة | E8: 6 | F8: Catering & Restaurant Services
A9: F&B | B9: 2 | C9: وجبات جاهزة - عبوات متنوعة جاهزة للأكل | E9: 7 | F9: Entertainment & Activities During Events
A10: METPHODOC | B10: 7 | C10: Advertising Services | E10: 8 | F10: Designing & Printing of Advertisement elements
A11: F&B | B11: 2 | C11: مشروبات غير كحولية متنوعة | E11: 9 | F11: Outdoors, Decoration & Boths Execution
A12: Enter | B12: 3 | C12: Entertainment Services | E12: 10 | F12: photo & videoes Documenteries & montage Services
A13: METBRANDEC | B13: 14 | C13: الدوریات المطبوعة | E13: 11 | F13: Ushering Services
A14: METARR | B14: 12 | C14: رحلات وخدمات سياحية | E14: 12 | F14: Giveaways
A15: Enter | B15: 3 | C15: حفلات وشو | E15: 13 | F15: Management Fees
A16: METBRANDEC | B16: 14 | C16: نماذج/أوراق العمل - المطبوعة مسبقاً
A17: METBRANDEC | B17: 14 | C17: خدمات الإعلان
A18: METPHODOC | B18: 7 | C18: تصوير فيديو
A19: METBRANDEC | B19: 14 | C19: دعاية واعلان
A20: BOTHP | B20: 4 | C20: إدارة و تنسيق الأحداث
A21: METARR | B21: 12 | C21: حدمات سياحيه مختلفه
A22: CARENT | B22: 15 | C22: نقل سياحي
A23: F&B | B23: 2 | C23: مجموعات متنوعة من الأغذية/المشروبات/التبغ
A24: METBSEQ | B24: 6 | C24: تأجير أجهزة صوت
A25: METBSEQ | B25: 6 | C25: تأجير أجهزة ومعدات حفلات
A26: METACC | B26: 10 | C26: خدمات الاقامة بالغرف
A27: F&B | B27: 2 | C27: ماكولات متنوعة
... A159: CARMIN | B159: 18 | C159: سيارات خاصه - جولدن

Sheet Bud_Itm_Mtble
A1: Item_Cat | B1: Item_Cat_ID | C1: Bud_Item_Des.
A2: METUSH | B2: 1 | C2: Ushers Totaling of (8F + 7M):
A3: METUSH | B3: 1 | C3: Ushers Uniforms - own black suit with white shirt - scarf for ladies / ties for gents
A4: F&B | B4: 2 | C4: Option A : St. Regis - Steak House
A5: Enter | B5: 3 | C5: Rana Arafa
A6: BOTHP | B6: 4 | C6: Poduim / Presenter Desk (specially designed with acrylic lighted logo)
A7: BOTHP | B7: 4 | C7: Side Banners
A8: BOTHP | B8: 4 | C8: Centerpieces - specially made with battery light / logo
A9: BOTHP | B9: 4 | C9: Branded Qubes (5 X 50cm)
A10: BOTHP | B10: 4 | C10: Branded Qubes (5 X 70cm)
A11: BOTHP | B11: 4 | C11: rental of 4 modern chairs (white) + 3 coffee tables
A12: BOTHP | B12: 4 | C12: Production of : Backwall 3m width X 3m height + wooden 1 logo
A13: BOTHP | B13: 4 | C13: Furniture - 2 bar stools + 1 wide counter table (2m) + on side 1 high table
... A176: Rev | B176: 8 | C176: VAT on Management Fees

Sheet PNR_Mtble
A1: CoCen_Key_ID | B1: PNR_ID | C1: Client ID | D1: Branch | E1: Event Name -Description | F1: Start Date | G1: End Date | H1: Size | I1: Venue | J1: Location | K1: Currancy | L1: Total cost | M1: Customer Name | N1: PO Refrance | O1: Electronic Invoice #
A2: 1 | B2: 9.22.C0002.1 | C2: C0002 | D2: Old Company | E2: Standalone 4 days / 3 nights 30 singles Athnes / Greece | M2: Sovalue
A3: 2 | B3: 9.22.C0002.2 | C3: C0002 | D3: Old Company | E3: Movenpick - SOMA BAY 40 Dubiles | M3: Sovalue
A4: 3 | B4: 1.23.C0006.3 | C4: C0006 | D4: Old Company | E4: Roundtable Meeting - Cairo ; Dusit Thani Hotel - New Cairo | M4: Cisco Systems Egypt Ltd.
A5: 4 | B5: 1.22.C0008.4 | C5: C0008 | D5: Old Company | E5: African Currency Forum 15-19 January, Luxor & Cairo, Egypt | M5: Reconnaissance International
A6: 5 | B6: 1.22.C0001.5 | C6: C0001 | D6: Old Company | E6: Luxor / Pediatric Nutrition Summit | M6: ABBOTT LABORATORIES | N6: 22419 / 22415
A7: 6 | B7: 1.22.C0001.6 | C7: C0001 | D7: Old Company | E7: Breakfast @ Oozy Rest. Beni Swief | M7: ABBOTT LABORATORIES | N7: 22439
A8: 7 | B8: 2.22.C0001.7 | C8: C0001 | D8: Old Company | E8: Lunch @ Lemon Café | M8: ABBOTT LABORATORIES | N8: 22423
A9: 8 | B9: 2.22.C0001.8 | C9: C0001 | D9: Old Company | E9: Lunch @ Sabahe Rest. | M9: ABBOTT LABORATORIES | N9: 23017
A10: 9 | B10: 2.22.C0001.9 | C10: C0001 | D10: Old Company | E10: ADC - Four Seasons 1st Residence | M10: ABBOTT LABORATORIES | N10: 4460
A11: 10 | B11: 3.22.C0001.10 | C11: C0001 | D11: Old Company | E11: Dr. M. Shamy Visa | M11: ABBOTT LABORATORIES | N11: 11029
A12: 11 | B12: 3.22.C0001.11 | C12: C0001 | D12: Old Company | E12: RCOG Ultra Sound - Hilton Heliopolis | M12: ABBOTT LABORATORIES | N12: 23193
A13: 12 | B13: 3.22.C0001.12 | C13: C0001 | D13: Old Company | E13: ART - Steigenbereger Tahrir | M13: ABBOTT LABORATORIES | N13: 23280
A14: 13 | B14: 3.22.C0001.13 | C14: C0001 | D14: Old Company | E14: Women Health - JW Marriott | M14: ABBOTT LABORATORIES | N14: 23512
A15: 14 | B15: 3.22.C0001.14 | C15: C0001 | D15: Old Company | E15: Predi Sure Balance | M15: ABBOTT LABORATORIES | N15: 23547 / 23554 / 23573
A16: 15 | B16: 3.22.C0001.15 | C16: C0001 | D16: Old Company | E16: ANI Meeting - Horus Menia | M16: ABBOTT LABORATORIES | N16: 23712
A17: 16 | B17: 4.22.C0001.16 | C17: C0001 | D17: Old Company | E17: Dr. M. Shamy Visa (accomm + Ticket + visa) | M17: ABBOTT LABORATORIES | N17: 11277
A18: 17 | B18: 4.22.C0001.17 | C18: C0001 | D18: Old Company | E18: MOH Public for Disability | M18: ABBOTT LABORATORIES | N18: 23798
A19: 18 | B19: 5.22.C0001.18 | C19: C0001 | D19: Old Company | E19: Trade SA - Holiday Inn - Cairo | M19: ABBOTT LABORATORIES | N19: 29094
A20: 19 | B20: 5.22.C0001.19 | C20: C0001 | D20: Old Company | E20: ADC - Four Seasons 1st Residence | M20: ABBOTT LABORATORIES | N20: 4479
A21: 20 | B21: 6.22.C0001.20 | C21: C0001 | D21: Old Company | E21: ADC - Alex Steigenberger Cecil | M21: ABBOTT LABORATORIES | N21: 4481
A22: 21 | B22: 6.22.C0001.21 | C22: C0001 | D22: Old Company | E22: Tele Health Conference - Four Seasona Nie | M22: ABBOTT LABORATORIES | N22: 5917
A23: 22 | B23: 6.22.C0001.22 | C23: C0001 | D23: Old Company | E23: Ramez Seddik Accommodation | M23: ABBOTT LABORATORIES | N23: 11390
A24: 23 | B24: 6.22.C0001.23 | C24: C0001 | D24: Old Company | E24: Standalone JW Marriott | M24: ABBOTT LABORATORIES | N24: 24457
A25: 24 | B25: 6.22.C0001.24 | C25: C0001 | D25: Old Company | E25: Standalone JW Marriott | M25: ABBOTT LABORATORIES
A26: 25 | B26: 6.22.C0001.25 | C26: C0001 | D26: Old Company | E26: Fairmont Cairo Standalone | M26: ABBOTT LABORATORIES | N26: 24443
A27: 26 | B27: 7.22.C0001.26 | C27: C0001 | D27: Old Company | E27: ADC - Meridien Airport | M27: ABBOTT LABORATORIES | N27: 4495
A28: 27 | B28: 8.22.C0001.27 | C28: C0001 | D28: Old Company | E28: Abbott EPD Influvac - Semiramis Cairo | M28: ABBOTT LABORATORIES | N28: 24837
A29: 28 | B29: 9.22.C0001.28 | C29: C0001 | D29: Old Company | E29: Abbott EPD Dinner - Babel Rest. | M29: ABBOTT LABORATORIES | N29: 11723
A30: 29 | B30: 9.22.C0001.29 | C30: C0001 | D30: Old Company | E30: Air ticket Luxor + Transfer favor | M30: ABBOTT LABORATORIES | N30: 25127
A31: 30 | B31: 10.22.C0001.30 | C31: C0001 | D31: Old Company | E31: 2 Visas Dubai | M31: ABBOTT LABORATORIES | N31: 11805
A32: 31 | B32: 10.22.C0001.31 | C32: C0001 | D32: Old Company | E32: Luxor Tickets + transfers c/o Dr. Essam Kaoud | M32: ABBOTT LABORATORIES | N32: 25506 /25445
A33: 32 | B33: 11.22.C0001.32 | C33: C0001 | D33: Old Company | E33: Ahmed El- Shafie Transportation to Fayoum Group meeting Haram/Fayoum/Haram 24 Nov 2022 | M33: ABBOTT LABORATORIES | N33: 25733- Dated Nov 18,22
A34: 33 | B34: 11.22.C0001.33 | C34: C0001 | D34: Old Company | E34: ADC Four Seasons 1st Residence | M34: ABBOTT LABORATORIES | N34: 4513
A35: 34 | B35: 11.22.C0001.34 | C35: C0001 | D35: Old Company | E35: Anaa Makarova Transportation Nov. 27 from Airport to Dusit Hotel | M35: ABBOTT LABORATORIES | N35: 12012- Dated Nov 18,22
A36: 35 | B36: 11.22.C0001.35 | C36: C0001 | D36: Old Company | E36: Abbott Advisory board Cairo - November 24 | M36: ABBOTT LABORATORIES | N36: 4513 & 4532 - Dated Sep11 & Oct19 -2022
A37: 36 | B37: 11.22.C0008.36 | C37: C0008 | D37: Old Company | E37: VISA Application Services Athnes / Greece Wif's | M37: Dr. Ahmed Hendy So Value
A38: 37 | B38: 3.23.C0007.37 | C38: C0007 | D38: Old Company | E38: Luxor & Aswan Nile Cruise Mr. Ehab Hanna | M38: Ehab Hanna
A39: 39 | B39: 1.23.C0029.39 | C39: C0029 | D39: Old Company | E39: African Currency Forum 15-19 January, Luxor & Cairo, Egypt | M39: Central Bank Of Egypt (banknote Printing Plant) The Association of African Banknotes and Security Document Printers.
A40: 40 | B40: 4.22.C0010.40 | C40: C0010 | D40: Old Company | E40: ICA Ministerial Meeting & ICCH Confrance October 2022 | M40: GV Developments
...

Sheet Sup_Mtbl
A1: Ven_ID | B1: Ven_Subled_Name | C1: Sup_Tax_Id | D1: Acc_Key | E1: Cost Center | F1: Relationship_Type | G1: Contact_Person | H1: Contact_Person_Title | I1: Contact_Person_Telephone_number | J1: Beneficiary | K1: Address | L1: Telephone_Number | M1: Email_Addres
A2: Bnk_Exp | B2: Bank Charges | D2: 39 | E2: FinanceCost
A3: Bnk_Trnz | B3: Bank Internal Transfer | D3: 8 | E3: FinanceCost
A4: V0001 | B4: STEIGENBERGER Nile Palace Luxor | C4: 204958482 | D4: 12 | E4: Apply | F4: Operating Vendor
A5: V0002 | B5: NORTH AFRICA FOR SHIPMENT AND NASCO TOURS | C5: 202452735 | D5: 12 | E5: Apply | F5: Operating Vendor
A6: V0003 | B6: LE MERIDIEN CAIRO AIRPORT | D6: 12 | E6: Apply | F6: Operating Vendor
A7: V0004 | B7: Unanmed Prinitng & Stationary Suppler | D7: 12 | E7: Apply | F7: Operating Vendor
A8: V0005 | B8: Movenpick Resort Soma Bay | C8: 286783649 | D8: 12 | E8: Apply | F8: Operating Vendor
A9: V0006 | B9: INTER CO MPANY FOR HOTEL TOURIS | D9: 12 | E9: Apply | F9: Operating Vendor
A10: V0007 | B10: SEMIRAMIS INTERCONTINENTAL | D10: 12 | E10: Apply | F10: Operating Vendor
A11: V0008 | B11: CAIRO MARRIOTT HOTEL | D11: 12 | E11: Apply | F11: Operating Vendor | G11: Engy Rashed | H11: Director of Sales | I11: 01200100014
A12: V0009 | B12: JW MARRIOTT HOTEL | D12: 12 | E12: Apply | F12: Operating Vendor
A13: V0010 | B13: M2 DEVELOPMENTS | D13: 12 | E13: Apply | F13: Operating Vendor
A14: V0011 | B14: Raed shekh | D14: 12 | E14: Apply | F14: Operating Vendor
A15: V0012 | B15: Unknwon | D15: 12 | E15: Apply | F15: Operating Vendor
A16: V0013 | B16: رفعت فتحى رمضان مرسى | D16: 12 | E16: Apply | F16: Operating Vendor
A17: V0014 | B17: Rixos Premium Seagate | C17: 200113720 | D17: 12 | E17: Apply | F17: Operating Vendor | L17: +20 69 3710130
A18: V0015 | B18: Royal Maxim Palace Kempinski | D18: 12 | E18: Apply | F18: Operating Vendor | G18: Ahmed Helmy | H18: Director of Sales | I18: 01119999949
A19: V0016 | B19: Hilton Cairo Heliopolis | D19: 12 | E19: Apply | F19: Operating Vendor | G19: Hossam Shehata | H19: Director of Sales | I19: 01222270655 | K19: URUBA STREET,HELIOPOLIS, CARIO EGYPT | L19: 02-2677730-40
A20: V0017 | B20: Pyramid Turizm IC DIC TIC Film Ve Reklam | D20: 12 | E20: Apply | F20: Operating Vendor | K20: ISTANBUL/TURKY
A21: V0018 | B21: FARAH NILE CRUISE | C21: 349700923 | D21: 12 | E21: Apply | F21: Operating Vendor | J21: Golden Nile Travel Service
A22: V0019 | B22: SAMEH Khalil Thabet Khalil | D22: 12 | E22: Apply | F22: Operating Vendor
A23: V0020 | B23: X-NATION High Technology & Events | C23: 628157576 | D23: 12 | E23: Apply | F23: Operating Vendor | K23: [224B, El Kawthar District - HRG] [Builiding H7, Downtown El Gouna] | L23: [0122 213 2929]
A24: V0021 | B24: NEXT AD-advertising and communications | C24: 540224502 | D24: 12 | E24: Apply | F24: Operating Vendor
A25: V0022 | B25: Jolie Ville Hotel Luxor | D25: 12 | E25: Apply | F25: Operating Vendor | G25: Wael Ragaay | H25: Director of Sales | I25: 01000480780
A26: V0023 | B26: Nile Air | D26: 12 | E26: Apply | F26: Operating Vendor
A27: V0024 | B27: SALMA ABDULLAH | D27: 12 | E27: Apply | F27: Operating Vendor
A28: V0025 | B28: Ahmed Mahmoud Aly Mohamed Barakat Photo grapher | C28: 623767406 | D28: 12 | E28: Apply | F28: Operating Vendor
A29: V0026 | B29: Jack Zakaria - DJ | D29: 12 | E29: Apply | F29: Operating Vendor
A30: V0027 | B30: Comtech Egypt Audio Visual Event Management | C30: 672422425 | D30: 12 | E30: Apply | F30: Operating Vendor
A31: V0028 | B31: Fairmont Nile City | D31: 12 | E31: Apply | F31: Operating Vendor
A32: V0029 | B32: Jonathan Cohen -Azimuth Marketing Communications | D32: 12 | E32: Apply | F32: Operating Vendor
A33: V0030 | B33: USHERS ACF | D33: 12 | E33: Apply | F33: Operating Vendor
A34: V0031 | B34: Music Life - Kahlied Al sahfi (Harfosh) | C34: 724028730 | D34: 12 | E34: Apply | F34: Operating Vendor
A35: V0032 | B35: Dusit Thani LakeView Cairo | C35: 301203199 | D35: 12 | E35: Apply | F35: Operating Vendor
A36: V0033 | B36: AIR CAIRO | D36: 12 | E36: Apply | F36: Operating Vendor
A37: V0034 | B37: Grand Nile Tower | D37: 12 | E37: Apply | F37: Operating Vendor | G37: Amira Salim
A38: V0035 | B38: Kempinski Nile Hotel Cairo | C38: 489481132 | D38: 12 | E38: Apply | F38: Operating Vendor
A39: V0036 | B39: Orange Telecom | D39: 12 | E39: Office Sustain Expenses | F39: Operating Vendor
A40: V0037 | B40: ENBD-EGP | D40: 12 | E40: FinanceCost | F40: Operating Vendor
...

Sheet Clnt_Mtbl
A1: Clnt_ID | B1: Clnt_Subled_Name | C1: Clnt_Tax_Id | D1: Acc_Key | E1: Client Address | F1: Telephone Number | G1: Contact Person | H1: Email Address
A2: C0001 | B2: Abbott Laboratories | C2: 200011898 | D2: 10 | E2: KTC Building, plot 76,First Sector, City Center, Fifth Settlement, New Cairo, Cairo, Egypt. | F2: ehab.abdelaziz@abbott.com www.abbott.com | G2: Ehab Abdelaziz Senior Accountant
A3: C0002 | B3: Sovalue | D3: 10
A4: C0003 | B4: MICROSOFT EGYPT LLC | C4: 200143573 | D4: 10 | F4: v-lelhadidy@microsoft.com | G4: Lina El-Hadidy Marketing Coordinator – Integrated Marketing MEA Marketing Service Desk
A5: C0006 | B5: Cisco Systems Egypt Ltd. | C5: 200190423 | D5: 10 | E5: City Stars Project - Tower 2 A Omar Ibn El Khattab St. - Nasr City Cairo 11771 Egypt | F5: +20-1223120009 | G5: Accounts Payable | H5: kahedaya@cisco.com
A6: C0007 | B6: Ehab Hanna | D6: 10 | E6: Ehab13@msn.com | H6: Ehab13@msn.com
A7: C0008 | B7: Reconnaissance International | D7: 10 | E7: 1B The Beacon, Beaufront Park, Anick Road, Hexham, Northumberland, NE46 4TU, UK. | F7: +44 (0) 1932 508 807 | G7: Weronika Komorowska-Conference Manager | H7: weronika@recon-intl.com
A8: C0009 | B8: Dr. Ahmed Hendy So Value | D8: 10
A9: C0010 | B9: GV Developments | D9: 10 | E9: 62 South Taseen Stret Fifth Settlement, New Cairo, Cairo, Egypt.
A10: C0011 | B10: Elixir Pharma | D10: 10 | E10: Cairo, Sheraton Building , Heliopolis
A11: C0012 | B11: رفعت فتحى رمضان مرسى | D11: 10
A12: C0013 | B12: INTER CO MPANY FOR HOTEL TOURIS | D12: 10
A13: C0014 | B13: Mr. Maged Sami | D13: 10
A14: C0015 | B14: IQ Structures s.r.o. | D14: 10 | E14: Hlavní 130 250 68 Husinec-Řež Czech Republic | G14: Romana Čermáková Back Office Manager katerina.cerna@iqstructures.cz; ‎
A15: C0016 | B15: Giesecke+Devrient Currency Technology GmbH | D15: 10 | E15: Giesecke+Devrient Currency Technology GmbH Prinzregentenstr. 161, 81677 Munich, Germany www.gi-de.com/ct | F15: M +49-173 5430534 | G15: Michaela Reichert Head of Conferences and Events | H15: michaela.reichert@gi-de.com
A16: C0017 | B16: De La Rue | D16: 10 | E16: Langston Road, Loughton, Essex, IG10 3PB, United Kingdom | F16: +44 (0)20 8502 8019 or 8020 | fax: +44 (0)20 8502 1007 | G16: Maria Atkinson Government Relations Manager | H16: maria.atkinson@uk.delarue.com
A17: C0018 | B17: Landqart AG | D17: 10 | E17: Kantonsstrasse 16 | 7302 Landquart | Switzerland | F17: +41 81 307 92 49 | Fax: +41 81 307 91 43
A18: C0019 | B18: Meta Materials Inc (META®) | D18: 10 | E18: 60 Highfield Park Dr, Suite 102 Dartmouth, NS Canada B3A 4R9 | F18: 1-604-765-0593 | G18: Erin Jones Global Events Manager | H18: erin.jones@metamaterial.com
A19: C0020 | B19: Luminescene | D19: 10 | E19: The Fairway, Harlow, Essex, CM18 6NG, UK www.luminescence-scs.com | F19: T: +44 (0)1279 456400 | G19: Gerben van Wijk Sales and Marketing Director M: +44 (0)7506 118412 | H19: gerben.vanwijk@luminescence-scs.com
A20: C0021 | B20: JURA SECURITY PRINTING | D20: 10 | E20: Company (client): Jura JSP GmbH Address: A-1190 Vienna, Gebhardtgasse 13., Austria VAT number: ATU39169109 | F20: +36 1 275 1250 | G20: Éva Móritz eva.moritz@jura.hu | H20: eva.moritz@jura.hu
A21: C0022 | B21: Koenig & Bauer Banknote Solutions SA | D21: 10 | E21: Avenue du Grey 55, CH-1018 Lausanne PO Box 347, CH-1000 Lausanne 22 Switzerland | F21: +41 21 345 71 33 | G21: i.A. Vanessa Lauzier Marketing Communications vanessa.lauzier@koenig-bauer.com | H21: banknote-solutions.koenig-bauer.com
A22: C0023 | B22: Orell Füssli Ltd | D22: 10 | E22: Dietzingerstrasse 3 8036 Zurich, Switzerland | F22: +41444667422 | G22: Meri Torniainen Director Marketing and Communication | H22: meri.torniainen@orellfuessli.com
A23: C0024 | B23: Security Fibres UK African | D23: 10
A24: C0025 | B24: OBERTHUR FIDUCIAIRE | D24: 10 | E24: www.oberthur-fiduciaire.com | F24: +33 1 42 99 77 25 | G24: Charlotte Lafont Group Communications Manager | H24: c.lafont@fcof.com
A25: C0026 | B25: Crane Currency | D25: 10 | E25: 30 Main Street Dalton, Massachusetts USA | G25: Tod L Niedeck Marketing Director | H25: tod.niedeck@cranecurrency.com
A26: C0027 | B26: IMPRIMERIE NATIONALE SA | D26: 10 | E26: RUE DE FRERES BEAUMONT 59128 FLERS EN ESCREBIEUX France | F26: +33(0)1 64 76 31 00 | G26: Mehdi Benmebarek Secure Components BU Communications Manager | H26: mehdi.benmebarek@ingroupe.com
A27: C0028 | B27: LEONHARD KURZ Stiftung & Co. KG | D27: 10 | E27: Schwabacher Str. 482 90763 Fürth www.kurz.de | F27: +49 911 7141 9653 | G27: Michelle Carter Assistant & Project Coordinator Business Area Security - Banknotes | H27: michelle.carter@kurz.de
A28: C0029 | B28: Central Bank Of Egypt (banknote Printing Plant) The Association of African Banknotes and Security Document Printers. | D28: 10 | E28: 214 pyramids Road , Giza 12556 | F28: 20235990622 | G28: Eng. Mostafa Tobbala General Manager Procurement & Logistic Dept. | H28: mostafa.tobbala@cbe.org.eg
A29: C0030 | B29: Klayy Tech | D29: 10 | E29: Cairo, Smart Village, Building 19B www.klayytech.com | F29: Mobile: +2 01223651081 | G29: Mr.Sayed Mohamed ,MBA | Accounting Manager.
A30: C0031 | B30: E- Finance Co | C30: 616359772 | D30: 10 | E30: Smart Village, Building B 115, 2nd floor,KM 28 Cairo-Alex Desert Road, 12585 | G30: islam_elgamal@efinance.com.eg
A31: C0032 | B31: E- Finance Co 2 | C31: 215864379 | D31: 10 | E31: Smart Village, Building B 115, 2nd floor,KM 28 Cairo-Alex Desert Road, 12585 | G31: islam_elgamal@efinance.com.eg
A32: C0037 | B32: Orion 360 | C32: 340441933 | D32: 10
A33: C0038 | B33: US-AID | C33: 699058155 | D33: 10
A34: C0158 | B34: The Brand Mechanics | C34: 158 | D34: 10 | E34: 201,Al Ameri Tower Barsha Heights (tecom) Dubai , UAE | F34: +971 4 5541706 | G34: Jennifer Melecio
A35: C0159 | B35: Direct Egypt | C35: 200203495 | D35: 10
A36: C0160 | B36: VAS & IT VALLY | D36: 10
A37: C0165 | B37: EAST WEST ADVE RTISING(L.L.C) | D37: 10
A38: C0170 | B38: information Technology of Egypt Corporation | C38: 200122886 | D38: 10
A39: C0180 | B39: TEAMSTOK FZCO | D39: 10
A40: C0181 | B40: وليد طارق احمد موافي و شريكة | D40: 10
...

Sheet Own_Mtbl
A1: Own_ Code | B1: Own_Subled_Name | C1: Acc_Key | D1: Cost Center | E1: Exp Account Name
A2: Bnk_Cur | B2: Bnk_Curr | C2: 4 | D2: FinanceCost
A3: Bnk_Eur | B3: Bnk_Eur | C3: 5 | D3: FinanceCost
A4: Bnk_Sav | B4: Bnk_Sav | C4: 6 | D4: FinanceCost
A5: Bnk_Usd | B5: Bnk_Usd | C5: 7 | D5: FinanceCost
A6: Bnk_Trnz | B6: Bnk_Trnz | C6: 8 | D6: FinanceCost
A7: Bnk_Exp | B7: Bnk_Exp | C7: 39 | D7: FinanceCost
A8: MR. MAGED ATM | B8: MR. MAGED ATM | C8: 17 | D8: Mr.MagedPersonal
A9: Mr. MAGED SAMI | B9: Mr. MAGED SAMI | C9: 17 | D9: Mr.MagedPersonal
A10: Own001 | B10: ELEGANT EDUCATION HOME LYCEE | C10: 17 | D10: Mr.MagedPersonal | E10: Owner Current Account
A11: Own002 | B11: SHERINE ERNEST TAKLA GHOBRANY | C11: 17 | D11: Mr.MagedPersonal | E11: Owner Current Account
A12: Own003 | B12: AMIR EZZAT NESSIM AMIR NESSIM | C12: 17 | D12: Mr.MagedPersonal | E12: Owner Current Account
A13: Own004 | B13: MAGED SAMI SAWIRES- General Manager | C13: 17 | D13: Mr.MagedPersonal | E13: Owner Current Account
A14: Own005 | B14: CIB VIA CARD MR. Maged | C14: 17 | D14: Mr.MagedPersonal | E14: Owner Current Account
A15: Own006 | B15: NBE Mr. Maged Personal Account | C15: 17 | D15: Mr.MagedPersonal | E15: Owner Current Account
A16: Own007 | B16: Zo Clinicst CAI | C16: 17 | D16: Mr.MagedPersonal | E16: Owner Current Account
A17: Own008 | B17: Zo Clinic | C17: 17 | D17: Mr.MagedPersonal | E17: Owner Current Account
A18: Own009 | B18: UROPIAN CO FOR TOUR | C18: 17 | D18: Mr.MagedPersonal | E18: Owner Current Account
A19: Own010 | B19: UROPIAN CO FOR | C19: 17 | D19: Mr.MagedPersonal | E19: Owner Current Account
A20: Own011 | B20: U BISTRO REST C | C20: 17 | D20: Mr.MagedPersonal | E20: Owner Current Account
A21: Own012 | B21: U Bistro CAIRO | C21: 17 | D21: Mr.MagedPersonal | E21: Owner Current Account
... A132: Own123 | B132: La Via En Rose | C132: 17 | D132: Mr.MagedPersonal | E132: Owner Current Account

Sheet Stff_Mtbl
A1: Stf_ Code | B1: Stff_Subled_Name | C1: Cost Center | D1: Acc_Key | E1: AP -Account Name | F1: Exp Account Name
A2: Stf-0001 | B2: REHAM HISHAM RAMADAN HASSAN - Operation Manger | C2: Apply | D2: 11 | E2: Staff Payables | F2: Indirect Salary
A3: Stf-0002 | B3: EMAD HAMZA AHMED | C3: Apply | D3: 11 | E3: Staff Payables | F3: Indirect Salary
A4: Stf-0003 | B4: RANIA ADNAN AYESH SABAWI - Marketing Manager | C4: Apply | D4: 11 | E4: Staff Payables | F4: Indirect Salary
A5: Stf-0004 | B5: Ahmed Salah Gawish - Finance Controllar | C5: Apply | D5: 11 | E5: Staff Payables | F5: Indirect Salary
A6: Stf-0005 | B6: Eng. Khalied Tawheid | C6: IT & Computer Devises Lap tops | D6: 11 | E6: Staff Payables | F6: Indirect Salary
A7: Stf-0006 | B7: Lina Guide | C7: Apply | D7: 11 | E7: Staff Payables | F7: Indirect Salary
A8: Stf-0007 | B8: Nourhan | C8: Apply | D8: 11 | E8: Staff Payables | F8: Indirect Salary
A9: Stf-0008 | B9: Mahmoud EL Kanja | C9: Apply | D9: 11 | E9: Staff Payables | F9: Indirect Salary
A10: Stf-0009 | B10: Amany Nabil guide | C10: Apply | D10: 11 | E10: Staff Payables | F10: Indirect Salary
A11: Stf-0010 | B11: Leqaa Mohamed ING | C11: Apply | D11: 11 | E11: Staff Payables | F11: Indirect Salary

Sheet Einv_TrxMtbl
A1: Einv_Elc_Id | B1: التوجية المحاسبي | C1: Acc_Key | D1: رقم الأقرار الضريبي أ-خالد | E1: رقم الأقرار الضريبي2 | F1: مركز التكلفة
A2: 02YZX5QDS0H7M5TE21BWE0RG10 | B2: ح / مصاريف التأسيس وما قبل التشغيل | C2: =VLOOKUP(Inv_Master[[#This Row],[التوجية المحاسبي]],'COA_Mtble'!C:D,2,0) -> 1 | D2: ما قبل نوفمبر 2023 | E2: ما قبل نوفمبر 2023 | F2: 39
A3: 03XXTNPM3AZQSP26ANZW5ZPJ10 | B3: أيرادات التشغيل المباشر | C3: =VLOOKUP(Inv_Master[[#This Row],[التوجية المحاسبي]],'COA_Mtble'!C:D,2,0) -> 18 | D3: مارس@ 2025 | E3: مارس@ 2025 | F3: 105
A4: 03YQT0FNBWCKVEVGN1JYTZ3K10 | C4: =VLOOKUP(Inv_Master[[#This Row],[التوجية المحاسبي]],'COA_Mtble'!C:D,2,0) -> #N/A | F4: 115
A5: 09RND2X0P2PF6SK0HQ1S9D6K10 | C5: =VLOOKUP(Inv_Master[[#This Row],[التوجية المحاسبي]],'COA_Mtble'!C:D,2,0) -> #N/A | F5: N/A Admin Expn
A6: 0AP9TAE40B302RG6WXWFM9RH10 | B6: تكاليف تشغيل مباشر - أقامات فندية وحجز قاعات | C6: =VLOOKUP(Inv_Master[[#This Row],[التوجية المحاسبي]],'COA_Mtble'!C:D,2,0) -> 22 | D6: أقرار ديسمبر 2024 معدل | E6: مارس @2024 | F6: 79
A7: 0D0M6NB34AH8V57G1RHYG64J10 | B7: تكاليف تشغيل مباشر - دعاية وأعلان أعمال ديكور وأكشاك عرض | C7: =VLOOKUP(Inv_Master[[#This Row],[التوجية المحاسبي]],'COA_Mtble'!C:D,2,0) -> 24 | D7: أقرار ديسمبر 2024 معدل | E7: أغسطس @2024 | F7: 84
A8: 0NPTRHP8E0CH8K5EK3J1MDTJ10 | B8: تكاليف تشغيل مباشر - أنتقالات داخلية | C8: =VLOOKUP(Inv_Master[[#This Row],[التوجية المحاسبي]],'COA_Mtble'!C:D,2,0) -> 20 | D8: مايو @2025 | E8: مايو @2025 | F8: 108
A9: 0PHJAWFGA339N85D0RR9QXSJ10 | B9: تكاليف تشغيل مباشر - تذاكر طيران | C9: =VLOOKUP(Inv_Master[[#This Row],[التوجية المحاسبي]],'COA_Mtble'!C:D,2,0) -> 23 | D9: أبريل @ 2025 | E9: أبريل @ 2025 | F9: 108
A10: 0RB6D37SJ4Y85SWD6A43Y30J10 | B10: تكاليف تشغيل مباشر - أقامات فندية وحجز قاعات | C10: =VLOOKUP(Inv_Master[[#This Row],[التوجية المحاسبي]],'COA_Mtble'!C:D,2,0) -> 22 | D10: أقرار ديسمبر 2024 معدل | E10: يونيو@2024 | F10: 82
A11: 0RR9FMS6B061CAWBQW3V79EJ10 | B11: تكاليف تشغيل مباشر - دعاية وأعلان أعمال ديكور وأكشاك عرض | C11: =VLOOKUP(Inv_Master[[#This Row],[التوجية المحاسبي]],'COA_Mtble'!C:D,2,0) -> 24 | D11: أقرار ديسمبر 2024 معدل | E11: ديسمبر@2024 | F11: 88
A12: 0WJYY6Z5F4X1A8XH8NKE4PMH10 | B12: أيرادات التشغيل المباشر | C12: =VLOOKUP(Inv_Master[[#This Row],[التوجية المحاسبي]],'COA_Mtble'!C:D,2,0) -> 18 | D12: أقرار ديسمبر 2024 معدل | E12: يناير @2024 | F12: 76
A13: 0XE20G1RMFHSP69MWWH1R7ZJ10 | B13: تكاليف تشغيل مباشر - دعاية وأعلان مطبوعات | C13: =VLOOKUP(Inv_Master[[#This Row],[التوجية المحاسبي]],'COA_Mtble'!C:D,2,0) -> 25 | D13: يوليو@2025 | E13: يوليو@2025 | F13: 107
A14: 14F4000482WM19JZ25KNGYMJ10 | B14: تكاليف تشغيل مباشر - أغذية ومشروبات | C14: =VLOOKUP(Inv_Master[[#This Row],[التوجية المحاسبي]],'COA_Mtble'!C:D,2,0) -> 21 | D14: فبراير @ 2025 | E14: فبراير @ 2025 | F14: 103
A15: 19KNXMQYN3HDJNH0ZG9DHHRH10 | B15: تكاليف تشغيل مباشر - أقامات فندية وحجز قاعات | C15: =VLOOKUP(Inv_Master[[#This Row],[التوجية المحاسبي]],'COA_Mtble'!C:D,2,0) -> 22 | D15: أقرار ديسمبر 2024 معدل | E15: مارس @2024 | F15: 81
A16: 1BDH75FHEW8ZVK6X8FWD7Q9H10 | B16: Canclled | C16: Canclled | D16: ما قبل نوفمبر 2023 | E16: ما قبل نوفمبر 2023 | F16: N/A Admin Expn
A17: 1GSFJ01TXK61NG61CZHNCB2J10 | B17: أيرادات التشغيل المباشر | C17: =VLOOKUP(Inv_Master[[#This Row],[التوجية المحاسبي]],'COA_Mtble'!C:D,2,0) -> 18 | D17: يوليو@2024 | E17: يوليو@2024 | F17: 84
A18: 1JNCGKMB1YKM4PS0SX5FD8FG10 | B18: ح / مصاريف التأسيس وما قبل التشغيل | C18: =VLOOKUP(Inv_Master[[#This Row],[التوجية المحاسبي]],'COA_Mtble'!C:D,2,0) -> 1 | D18: ما قبل نوفمبر 2023 | E18: ما قبل نوفمبر 2023 | F18: 2
A19: 1MZ9KQ2DQTZYY257QW2Y3NWH10 | B19: تكاليف تشغيل مباشر - أنتقالات داخلية | C19: =VLOOKUP(Inv_Master[[#This Row],[التوجية المحاسبي]],'COA_Mtble'!C:D,2,0) -> 20 | D19: أقرار ديسمبر 2024 معدل | E19: أبريل@2024 | F19: 82
A20: 1N3WZG7KPA784HY4864YA5RH10 | B20: أيرادات التشغيل المباشر | C20: =VLOOKUP(Inv_Master[[#This Row],[التوجية المحاسبي]],'COA_Mtble'!C:D,2,0) -> 18 | D20: أقرار ديسمبر 2024 معدل | E20: مارس @2024 | F20: 79
A21: 1Y0W47Z445PCDQ4VJ3W63EGH10 | B21: مصروفات أدارية وعمومية - تكنولوجيا المعلومات و أدوات مكتبية | C21: =VLOOKUP(Inv_Master[[#This Row],[التوجية المحاسبي]],'COA_Mtble'!C:D,2,0) -> 32 | D21: نوفمبر@2023 | E21: نوفمبر@2023 | F21: N/A Admin Expn
A22: 21VC5FZADWGKY30PFQ95T3TJ10 | B22: تكاليف تشغيل مباشر - أنتقالات داخلية | C22: =VLOOKUP(Inv_Master[[#This Row],[التوجية المحاسبي]],'COA_Mtble'!C:D,2,0) -> 20 | D22: أبريل @ 2025 | E22: أبريل @ 2025 | F22: 108
A23: 26VQK4FVS6BFAW8S5FAKM1SJ10 | B23: تكاليف تشغيل مباشر - تذاكر طيران | C23: =VLOOKUP(Inv_Master[[#This Row],[التوجية المحاسبي]],'COA_Mtble'!C:D,2,0) -> 23 | D23: أبريل @ 2025 | E23: أبريل @ 2025 | F23: Mr.MagedPersonal
A24: 2C3ABMN90AE7DFS43NXM7XMH10 | B24: مصروفات أدارية وعمومية - تكنولوجيا المعلومات و أدوات مكتبية | C24: =VLOOKUP(Inv_Master[[#This Row],[التوجية المحاسبي]],'COA_Mtble'!C:D,2,0) -> 32 | D24: أقرار ديسمبر 2024 معدل | E24: يناير @2024 | F24: N/A Admin Expn
A25: 2C8XES2YM0YQZPACZYAN27SJ10 | B25: تكاليف تشغيل مباشر - أغذية ومشروبات | C25: =VLOOKUP(Inv_Master[[#This Row],[التوجية المحاسبي]],'COA_Mtble'!C:D,2,0) -> 21 | D25: أبريل @ 2025 | E25: أبريل @ 2025 | F25: 110
A26: 2DX6HT44M15C0BBV33VMACBJ10 | B26: مصروفات أدارية وعمومية - تكنولوجيا المعلومات و أدوات مكتبية | C26: =VLOOKUP(Inv_Master[[#This Row],[التوجية المحاسبي]],'COA_Mtble'!C:D,2,0) -> 32 | D26: أقرار ديسمبر 2024 معدل | E26: أكتوبر@2024 | F26: N/A Admin Expn
A27: 2GE0XBFZ7M4A19KQ8T2J9TZJ10 | B27: تكاليف تشغيل مباشر - دعاية وأعلان أعمال ديكور وأكشاك عرض | C27: =VLOOKUP(Inv_Master[[#This Row],[التوجية المحاسبي]],'COA_Mtble'!C:D,2,0) -> 24 | D27: يوليو@2025 | E27: يوليو@2025 | F27: 113
A28: 2NE02KB5WMJ0AMMM49EQ3A6K10 | C28: =VLOOKUP(Inv_Master[[#This Row],[التوجية المحاسبي]],'COA_Mtble'!C:D,2,0) -> #N/A | F28: 115
A29: 2RQ0XG5SGDMRY3VG89TSE3JH10 | B29: تكاليف تشغيل مباشر - أقامات فندية وحجز قاعات | C29: =VLOOKUP(Inv_Master[[#This Row],[التوجية المحاسبي]],'COA_Mtble'!C:D,2,0) -> 22 | D29: ديسمبر@2023 | E29: ديسمبر@2023 | F29: 72
A30: 2S5E44XDV4YJKD8VQ7J3HVSJ10 | B30: تكاليف تشغيل مباشر - دعاية وأعلان أعمال ديكور وأكشاك عرض | C30: =VLOOKUP(Inv_Master[[#This Row],[التوجية المحاسبي]],'COA_Mtble'!C:D,2,0) -> 24 | D30: أبريل @ 2025 | E30: أبريل @ 2025 | F30: 109
A31: 2WPKX9CDVBPS1X2H2VXTXV1J10 | B31: أيرادات التشغيل المباشر | C31: =VLOOKUP(Inv_Master[[#This Row],[التوجية المحاسبي]],'COA_Mtble'!C:D,2,0) -> 18 | D31: يوليو@2024 | E31: يوليو@2024 | F31: 84
A32: 32NGZ3R77W695NM3751425VJ10 | B32: تكاليف تشغيل مباشر - تذاكر طيران | C32: =VLOOKUP(Inv_Master[[#This Row],[التوجية المحاسبي]],'COA_Mtble'!C:D,2,0) -> 23 | D32: مايو @2025 | E32: مايو @2025 | F32: 108
A33: 33VPZH7A3TPHFGGZDCQHZZ5K10 | C33: =VLOOKUP(Inv_Master[[#This Row],[التوجية المحاسبي]],'COA_Mtble'!C:D,2,0) -> #N/A | F33: 119
A34: 34NGJN6GTE4E6RM8PEVYSEGJ10 | B34: مصروفات أدارية وعمومية - تكنولوجيا المعلومات و أدوات مكتبية | C34: =VLOOKUP(Inv_Master[[#This Row],[التوجية المحاسبي]],'COA_Mtble'!C:D,2,0) -> 32 | D34: أقرار ديسمبر 2024 معدل | E34: ديسمبر@2024 | F34: Mercedes-Benz - Assets 592.ق.ط.ب
A35: 34QV2AQ3VGM95FGYR1QBB8QH10 | B35: تكاليف تشغيل مباشر - دعاية وأعلان تصوير وتوثيق الفعليات | C35: =VLOOKUP(Inv_Master[[#This Row],[التوجية المحاسبي]],'COA_Mtble'!C:D,2,0) -> 26 | D35: أقرار ديسمبر 2024 معدل | E35: فبراير@2024 | F35: 78
A36: 389SWW7TQ0PXD057QEZR1Q6K10 | C36: =VLOOKUP(Inv_Master[[#This Row],[التوجية المحاسبي]],'COA_Mtble'!C:D,2,0) -> #N/A | F36: 115
A37: 390AM81A1GQQ7EC2MB8JNW8J10 | B37: تكاليف تشغيل مباشر - دعاية وأعلان تأجير شاشات عرض ومؤثرات صوتية ومعدات إضاءة | C37: =VLOOKUP(Inv_Master[[#This Row],[التوجية المحاسبي]],'COA_Mtble'!C:D,2,0) -> 29 | D37: أقرار ديسمبر 2024 معدل | E37: سبتمبر@2024 | F37: 85
A38: 3K5K62V9NB41ZQ2XMHT22HKJ10 | B38: تكاليف تشغيل مباشر - دعاية وأعلان مطبوعات | C38: =VLOOKUP(Inv_Master[[#This Row],[التوجية المحاسبي]],'COA_Mtble'!C:D,2,0) -> 25 | D38: فبراير @ 2025 | E38: فبراير @ 2025 | F38: 103
A39: 3N4ZTDH7B51MF6BVCT6F6HPH10 | B39: أيرادات التشغيل المباشر | C39: =VLOOKUP(Inv_Master[[#This Row],[التوجية المحاسبي]],'COA_Mtble'!C:D,2,0) -> 18 | D39: فبراير@2024 | E39: فبراير@2024 | F39: 71
A40: 3NX66PMN1D1GXCFSMAQN1E6K10 | C40: =VLOOKUP(Inv_Master[[#This Row],[التوجية المحاسبي]],'COA_Mtble'!C:D,2,0) -> #N/A | F40: 115
...

Sheet Bud_Pur_Trxtbl
A1: PNR_ID | B1: Assigned to supplier | C1: Ven_ID | D1: Item Des. | E1: Units | F1: no of nightsn
A2: 04.25.C0003.110 | B2: ABU GHALI TUR | C2: V-0098 | D2: Car with driver at disposal for 8hrs (Mercedes E class - 2019) | E2: 1 | F2: 1
A3: 05.25.C0202.108 | B3: Momento Iman Thaha Naouf | C3: V-0061 | D3: *Gala Dinner Sound System Incl Stage system +sound system + light system+LED Screen | E3: 1 | F3: 1
A4: 05.25.C0202.108 | B4: Momento Iman Thaha Naouf | C4: V-0061 | D4: stage + 3*2 LED Screen
A5: 02.25.C0180.102 | B5: Ahmed Mahmoud Aly Mohamed Barakat Photo grapher | C5: V-0025 | D5: Photo Shooting | E5: 1 | F5: 1
A6: 02.25.C0180.102 | B6: Ahmed Mahmoud Aly Mohamed Barakat Photo grapher | C6: V-0025 | D6: Video Shooting | E6: 1 | F6: 1
A7: 02.25.C0180.102 | B7: Ahmed Mahmoud Aly Mohamed Barakat Photo grapher | C7: V-0025 | D7: Promo Movie : 2-3min movie for the whole event & main highlights with montage & effects | E7: 1 | F7: 1
A8: 02.25.C0180.102 | B8: Ahmed Mahmoud Aly Mohamed Barakat Photo grapher | C8: V-0025 | D8: Photo Printing - on spot | E8: 1 | F8: 1
A9: 03.25.C0003.105 | B9: Ahmed Mahmoud Aly Mohamed Barakat Photo grapher | C9: V-0025 | D9: Video Shooting | E9: 1 | F9: 1
A10: 03.25.C0003.105 | B10: Ahmed Mahmoud Aly Mohamed Barakat Photo grapher | C10: V-0025 | D10: Promo Movie : 2-3min movie for the whole event & main highlights with montage & effects | E10: 1 | F10: 1
A11: 03.25.C0003.105 | B11: Ahmed Mahmoud Aly Mohamed Barakat Photo grapher | C11: V-0025 | D11: Photo Shooting | E11: 1 | F11: 1
A12: 05.25.C0202.108 | B12: Ahmed Mahmoud Aly Mohamed Barakat Photo grapher | C12: V-0025 | D12: Daily Full photo & video shooting (throughout the whole day) - 2 shifts | E12: 1 | F12: 3
A13: 05.25.C0202.108 | B13: Ahmed Mahmoud Aly Mohamed Barakat Photo grapher | C13: V-0025 | D13: Promo Movie; 3-5min of the whole event with montage & effects | E13: 1 | F13: 1
A14: 04.25.C0003.109 | B14: Ahmed Mahmoud Aly Mohamed Barakat Photo grapher | C14: V-0025 | D14: Photo Shooting | E14: 1 | F14: 1
A15: 04.25.C0003.109 | B15: Ahmed Mahmoud Aly Mohamed Barakat Photo grapher | C15: V-0025 | D15: Video Shooting | E15: 1 | F15: 0
A16: 04.25.C0003.109 | B16: Ahmed Mahmoud Aly Mohamed Barakat Photo grapher | C16: V-0025 | D16: Promo Movie : 2-3min movie for the whole event & main highlights with montage & effects | E16: 1 | F16: 0
... A19: 04.25.C0003.110 | B19: Ariz | C19: V-0094 | D19: Catering - MS Office | E19: 1 | F19: 1
A20: 05.25.C0202.108 | B20: Aspire for Traning | C20: V-0092 | D20: Special Team Activity (combining wellness with physical activity & productivity)
A21: 04.25.C0003.109 | B21: B. Brand | C21: V-0091 | D21: 2 -Media Walla | E21: 1 | F21: 1
A22: 04.25.C0003.109 | B22: B. Brand | C22: V-0091 | D22: 4- Main screen Frame / Backdrop | E22: 1 | F22: 1
A23: 04.25.C0003.109 | B23: B. Brand | C23: V-0091 | D23: Poduim with logo & back lights
A24: 04.25.C0003.109 | B24: B. Brand | C24: V-0091 | D24: 1- Gate | E24: 1 | F24: 1
A25: 05.25.C0202.108 | B25: CAIRO Trade | C25: V-0088 | D25: ** Cooler Box 20 ltr | E25: 65 | F25: 1
A26: 04.25.C0003.109 | B26: CAIRO Trade | C26: V-0088 | D26: Option 1 Cooler box | E26: 8 | F26: 1
A27: 05.25.C0202.108 | B27: CARNIVAL SAMEH Egyptian Art for Show | C27: V-0087 | D27: Gala Dinner Entretainment Options : Trio
A28: 04.25.C0003.109 | B28: Comtech Egypt Audio Visual Event Management | C28: V-0027 | D28: 8m width X 2m depth X 0.4m height with stairs | E28: 1 | F28: 1
A29: 04.25.C0003.109 | B29: Comtech Egypt Audio Visual Event Management | C29: V-0027 | D29: on ground screens for presenters & speakers - in sync with the main screen | E29: 1 | F29: 1
A30: 04.25.C0003.109 | B30: Comtech Egypt Audio Visual Event Management | C30: V-0027 | D30: LED screen - for multi usage of presentation & as branding backdrop / P2 - 4m width X 3m height | E30: 12 | F30: 1
A31: 04.25.C0003.109 | B31: Comtech Egypt Audio Visual Event Management | C31: V-0027 | D31: 2 LED Towers (Each 3*1) | E31: 6 | F31: 1
A32: 04.25.C0003.109 | B32: Comtech Egypt Audio Visual Event Management | C32: V-0027 | D32: Basic Sound System - with 2 wireless mics | E32: 1 | F32: 1
A33: 04.25.C0003.109 | B33: Comtech Egypt Audio Visual Event Management | C33: V-0027 | D33: 3- LED Towers (each 1m width X 3m height) | E33: 2 | F33: 3
A34: 02.25.C0180.102 | B34: Comtech Egypt Audio Visual Event Management | C34: V-0027 | D34: 2 main LED screens on sides (each 4m width X 3m height) - totaling 24 meters screens | E34: 24 | F34: 1.5
A35: 02.25.C0180.102 | B35: Comtech Egypt Audio Visual Event Management | C35: V-0027 | D35: Extra Screens (sides & ceiling) - dimensions estimated | E35: 20 | F35: 1.5
A36: 02.25.C0180.102 | B36: Comtech Egypt Audio Visual Event Management | C36: V-0027 | D36: Media Server | E36: 1 | F36: 1.5
A37: 02.25.C0180.102 | B37: Comtech Egypt Audio Visual Event Management | C37: V-0027 | D37: Backdrop framing 2 screens + 1 banner in middle with acrylic logo/s & die cuts (totaling 14m width X 5 height) | E37: 1
A38: 02.25.C0180.102 | B38: Comtech Egypt Audio Visual Event Management | C38: V-0027 | D38: on ground screens for presenters & speakers - in sync with the main screen + 1 timer | E38: 3 | F38: 1
A39: 02.25.C0180.102 | B39: Comtech Egypt Audio Visual Event Management | C39: V-0027 | D39: Rental of professonal sound system ; high speakers, speakers surround, microphones (4 headsets + 2 handheld) , rack | E39: 1 | F39: 1
A40: 02.25.C0180.102 | B40: Comtech Egypt Audio Visual Event Management | C40: V-0027 | D40: Rental of professional light system (Clay Packy) - inclusive of moving heads, trusses, wash lights, beams, profiles, etc.. | E40: 1 | F40: 1
A41: 02.25.C0180.102 | B41: Comtech Egypt Audio Visual Event Management | C41: V-0027 | D41: LED Towers (each 1m width X 3m height) for messages, solgans, logo/s | E41: 4 | F41: 3
A42: 02.25.C0180.102 | B42: Comtech Egypt Audio Visual Event Management | C42: V-0027 | D42: LED / Plazma - 40inch - TV | E42: 4 | F42: 1.5
...

Sheet Bud_Sal_Trxtbl
A1: PNR_ID | B1: Clnt_ID | C1: Item Des. | D1: Units | E1: no of nightsn | F1: Cost | G1: Gross Budget Sales VAT Included | H1: Currency | I1: Conversion
A2: 02.25.C0180.102 | B2: =MID(Bud_Sal_Trxtbl[[#This Row],[PNR_ID]],7,5) -> C0180 | C2: Ushers Totaling of (8F + 7M): | D2: 15 | E2: 1 | F2: 32 | G2: 547.2 | H2: USD | I2: 50.75
A3: 02.25.C0180.102 | B3: =MID(Bud_Sal_Trxtbl[[#This Row],[PNR_ID]],7,5) -> C0180 | C3: Ushers Uniforms - own black suit with white shirt - scarf for ladies / ties for gents | D3: 15 | E3: 1 | F3: 6.3 | G3: 107.73 | H3: USD | I3: 50.75
A4: 02.25.C0180.102 | B4: =MID(Bud_Sal_Trxtbl[[#This Row],[PNR_ID]],7,5) -> C0180 | C4: Option A : St. Regis - Steak House | D4: 25 | E4: 1 | F4: 165 | G4: 4702.5 | H4: USD | I4: 50.75
A5: 02.25.C0180.102 | B5: =MID(Bud_Sal_Trxtbl[[#This Row],[PNR_ID]],7,5) -> C0180 | C5: Rana Arafa | D5: 1 | E5: 1 | G5: 3249 | H5: USD | I5: 50.75
A6: 02.25.C0180.102 | B6: =MID(Bud_Sal_Trxtbl[[#This Row],[PNR_ID]],7,5) -> C0180 | C6: Poduim / Presenter Desk (specially designed with acrylic lighted logo) | D6: 1 | E6: 1 | F6: 235 | G6: 267.9 | H6: USD | I6: 50.75
A7: 02.25.C0180.102 | B7: =MID(Bud_Sal_Trxtbl[[#This Row],[PNR_ID]],7,5) -> C0180 | C7: Side Banners | D7: 2 | E7: 1 | F7: 265 | G7: 604.2 | H7: USD | I7: 50.75
A8: 02.25.C0180.102 | B8: =MID(Bud_Sal_Trxtbl[[#This Row],[PNR_ID]],7,5) -> C0180 | C8: Centerpieces - specially made with battery light / logo | D8: 30 | E8: 1 | F8: 40 | G8: 1368 | H8: USD | I8: 50.75
A9: 02.25.C0180.102 | B9: =MID(Bud_Sal_Trxtbl[[#This Row],[PNR_ID]],7,5) -> C0180 | C9: Branded Qubes (5 X 50cm) | D9: 5 | E9: 1 | F9: 65 | G9: 370.5 | H9: USD | I9: 50.75
A10: 02.25.C0180.102 | B10: =MID(Bud_Sal_Trxtbl[[#This Row],[PNR_ID]],7,5) -> C0180 | C10: Branded Qubes (5 X 70cm) | D10: 5 | E10: 1 | F10: 75 | G10: 427.5 | H10: USD | I10: 50.75
A11: 02.25.C0180.102 | B11: =MID(Bud_Sal_Trxtbl[[#This Row],[PNR_ID]],7,5) -> C0180 | C11: rental of 4 modern chairs (white) + 3 coffee tables | D11: Packaged | G11: 282.72 | H11: USD | I11: 50.75
A12: 02.25.C0180.102 | B12: =MID(Bud_Sal_Trxtbl[[#This Row],[PNR_ID]],7,5) -> C0180 | C12: Production of : Backwall 3m width X 3m height + wooden 1 logo | D12: 4 | E12: 1 | F12: 1445 | G12: 6589.2 | H12: USD | I12: 50.75
A13: 02.25.C0180.102 | B13: =MID(Bud_Sal_Trxtbl[[#This Row],[PNR_ID]],7,5) -> C0180 | C13: Furniture - 2 bar stools + 1 wide counter table (2m) + on side 1 high table | D13: 4 | E13: 1 | F13: 276 | G13: 1258.56 | H13: USD | I13: 50.75
A14: 02.25.C0180.102 | B14: =MID(Bud_Sal_Trxtbl[[#This Row],[PNR_ID]],7,5) -> C0180 | C14: Production of : Backwall 3m width X 3m height + wooden 1 logo | D14: 1 | E14: 1 | F14: 2410 | G14: 2747.4 | H14: USD | I14: 50.75
A15: 02.25.C0180.102 | B15: =MID(Bud_Sal_Trxtbl[[#This Row],[PNR_ID]],7,5) -> C0180 | C15: Furniture - 2 bar stools + 1 wide counter table (2m) + on side 1 high table | D15: 1 | E15: 1 | F15: 276 | G15: 314.64 | H15: USD | I15: 50.75
A16: 02.25.C0180.102 | B16: =MID(Bud_Sal_Trxtbl[[#This Row],[PNR_ID]],7,5) -> C0180 | C16: Wooden walls production between booths with 3D event logos | D16: 5 | E16: 1 | F16: 396 | G16: 2257.2 | H16: USD | I16: 50.75
A17: 02.25.C0180.102 | B17: =MID(Bud_Sal_Trxtbl[[#This Row],[PNR_ID]],7,5) -> C0180 | C17: high tables set (each 1 table with 4 chairs) | D17: 10 | E17: 1 | F17: 87.6 | G17: 998.64 | H17: USD | I17: 50.75
A18: 02.25.C0180.102 | B18: =MID(Bud_Sal_Trxtbl[[#This Row],[PNR_ID]],7,5) -> C0180 | C18: 4m width X 3m height with die cut logo | D18: 1 | E18: 1 | G18: 969 | H18: USD | I18: 50.75
A19: 02.25.C0180.102 | B19: =MID(Bud_Sal_Trxtbl[[#This Row],[PNR_ID]],7,5) -> C0180 | C19: specially designed long desk - with backwall - diecuts & LED profiles lighting & acrylic logo | D19: 1 | E19: 1 | F19: 1500 | G19: 1710 | H19: USD | I19: 50.75
A20: 02.25.C0180.102 | B20: =MID(Bud_Sal_Trxtbl[[#This Row],[PNR_ID]],7,5) -> C0180 | C20: e-invitation + QR - code / registration | D20: 1 | E20: 1 | F20: 250 | G20: 285 | H20: USD | I20: 50.75
A21: 02.25.C0180.102 | B21: =MID(Bud_Sal_Trxtbl[[#This Row],[PNR_ID]],7,5) -> C0180 | C21: Photo Booth | D21: 1 | E21: 1 | G21: 1687.2 | H21: USD | I21: 50.75
A22: 02.25.C0180.102 | B22: =MID(Bud_Sal_Trxtbl[[#This Row],[PNR_ID]],7,5) -> C0180 | C22: 3D Mockup | D22: 1 | E22: 1 | G22: 963.3 | H22: USD | I22: 50.75
A23: 02.25.C0180.102 | B23: =MID(Bud_Sal_Trxtbl[[#This Row],[PNR_ID]],7,5) -> C0180 | C23: 2 lounges - each 2 sofas (3 seaters but for 2) + 2 arm chairs | D23: 2 | E23: 1 | F23: 247 | G23: 563.16 | H23: USD | I23: 50.75
A24: 02.25.C0180.102 | B24: =MID(Bud_Sal_Trxtbl[[#This Row],[PNR_ID]],7,5) -> C0180 | C24: ** Designing fees - 3D | D24: 1 | E24: 1 | G24: 1140 | H24: USD | I24: 50.75
A25: 02.25.C0180.102 | B25: =MID(Bud_Sal_Trxtbl[[#This Row],[PNR_ID]],7,5) -> C0180 | C25: ** Transportation & assembling / disambling of : (screens, AV, stages, production, …) | D25: 1 | E25: 1 | G25: 1710 | H25: USD | I25: 50.75
A26: 02.25.C0180.102 | B26: =MID(Bud_Sal_Trxtbl[[#This Row],[PNR_ID]],7,5) -> C0180 | C26: Name Tags &Lanyards | D26: 220 | E26: 1 | F26: 3.2 | G26: 802.56 | H26: USD | I26: 50.75
A27: 02.25.C0180.102 | B27: =MID(Bud_Sal_Trxtbl[[#This Row],[PNR_ID]],7,5) -> C0180 | C27: Direction Signs | D27: 8 | E27: 1 | F27: 68 | G27: 620.16 | H27: USD | I27: 50.75
A28: 02.25.C0180.102 | B28: =MID(Bud_Sal_Trxtbl[[#This Row],[PNR_ID]],7,5) -> C0180 | C28: Shirts with embroiderad 2 logos | D28: 20 | E28: 1 | F28: 10.5 | G28: 239.4 | H28: USD | I28: 50.75
A29: 02.25.C0180.102 | B29: =MID(Bud_Sal_Trxtbl[[#This Row],[PNR_ID]],7,5) -> C0180 | C29: Printing of Special Parking Cards | D29: 250 | E29: 1 | F29: 1.5 | G29: 427.5 | H29: USD | I29: 50.75
A30: 02.25.C0180.102 | B30: =MID(Bud_Sal_Trxtbl[[#This Row],[PNR_ID]],7,5) -> C0180 | C30: for background music throughout the day - with 12 channels mixer | D30: 1 | E30: 1 | F30: 320 | G30: 364.8 | H30: USD | I30: 50.75
A31: 02.25.C0180.102 | B31: =MID(Bud_Sal_Trxtbl[[#This Row],[PNR_ID]],7,5) -> C0180 | C31: additional mixers for other areas | D31: 2 | E31: 1 | F31: 120 | G31: 273.6 | H31: USD | I31: 50.75
A32: 02.25.C0180.102 | B32: =MID(Bud_Sal_Trxtbl[[#This Row],[PNR_ID]],7,5) -> C0180 | C32: 2 main LED screens on sides (each 4m width X 3m height) - totaling 24 meters screens | D32: 24 | E32: 1.5 | F32: 31.7 | G32: 1300.968 | H32: USD | I32: 50.75
A33: 02.25.C0180.102 | B33: =MID(Bud_Sal_Trxtbl[[#This Row],[PNR_ID]],7,5) -> C0180 | C33: Extra Screens (sides & ceiling) - dimensions estimated | D33: 20 | E33: 1.5 | F33: 31.7 | G33: 1084.14 | H33: USD | I33: 50.75
A34: 02.25.C0180.102 | B34: =MID(Bud_Sal_Trxtbl[[#This Row],[PNR_ID]],7,5) -> C0180 | C34: Media Server | D34: 1 | E34: 1.5 | F34: 380.5 | G34: 650.655 | H34: USD | I34: 50.75
A35: 02.25.C0180.102 | B35: =MID(Bud_Sal_Trxtbl[[#This Row],[PNR_ID]],7,5) -> C0180 | C35: Backdrop framing 2 screens + 1 banner in middle with acrylic logo/s & die cuts (totaling 14m width X 5 height) | D35: 1 | G35: 4702.5 | H35: USD | I35: 50.75
A36: 02.25.C0180.102 | B36: =MID(Bud_Sal_Trxtbl[[#This Row],[PNR_ID]],7,5) -> C0180 | C36: on ground screens for presenters & speakers - in sync with the main screen + 1 timer | D36: 3 | E36: 1 | F36: 42.5 | G36: 145.35 | H36: USD | I36: 50.75
A37: 02.25.C0180.102 | B37: =MID(Bud_Sal_Trxtbl[[#This Row],[PNR_ID]],7,5) -> C0180 | C37: Rental of professonal sound system ; high speakers, speakers surround, microphones (4 headsets + 2 handheld) , rack | D37: 1 | E37: 1 | G37: 1083 | H37: USD | I37: 50.75
A38: 02.25.C0180.102 | B38: =MID(Bud_Sal_Trxtbl[[#This Row],[PNR_ID]],7,5) -> C0180 | C38: Rental of professional light system (Clay Packy) - inclusive of moving heads, trusses, wash lights, beams, profiles, etc.. | D38: 1 | E38: 1 | G38: 1368 | H38: USD | I38: 50.75
A39: 02.25.C0180.102 | B39: =MID(Bud_Sal_Trxtbl[[#This Row],[PNR_ID]],7,5) -> C0180 | C39: LED Towers (each 1m width X 3m height) for messages, solgans, logo/s | D39: 4 | E39: 3 | F39: 31.7 | G39: 433.656 | H39: USD | I39: 50.75
A40: 02.25.C0180.102 | B40: =MID(Bud_Sal_Trxtbl[[#This Row],[PNR_ID]],7,5) -> C0180 | C40: LED / Plazma - 40inch - TV | D40: 4 | E40: 1.5 | F40: 55 | G40: 376.2 | H40: USD | I40: 50.75
...
